Workbook

Sheet Dashboard
A1: 12-Week Heavy SF Hybrid Training Log
A3: Use the Week 01–Week 12 tabs. Each week is split into Day 1–Day 7 sections with its own logging table.
A5: Week | B5: Planned Running Miles | C5: Actual Running Miles | D5: Readiness Score | E5: Heavy Focus | F5: Status | G5: Notes | H5: Sheet
A6: 1 | B6: 16 | C6: ='Week 01'!C3 -> Actual Run Miles | D6: ='Week 01'!C6 -> 0 | E6: Heavy strength + running | H6: Week 01
A7: 2 | B7: 18 | C7: ='Week 02'!C3 -> Actual Run Miles | D7: ='Week 02'!C6 -> 0 | E7: Heavy strength + running | H7: Week 02
A8: 3 | B8: 20 | C8: ='Week 03'!C3 -> Actual Run Miles | D8: ='Week 03'!C6 -> 0 | E8: Heavy strength + running | H8: Week 03
A9: 4 | B9: 15 | C9: ='Week 04'!C3 -> Actual Run Miles | D9: ='Week 04'!C6 -> 0 | E9: Heavy strength + running | H9: Week 04
A10: 5 | B10: 21 | C10: ='Week 05'!C3 -> Actual Run Miles | D10: ='Week 05'!C6 -> 0 | E10: Heavy strength + running | H10: Week 05
A11: 6 | B11: 23 | C11: ='Week 06'!C3 -> Actual Run Miles | D11: ='Week 06'!C6 -> 0 | E11: Heavy strength + running | H11: Week 06
A12: 7 | B12: 25 | C12: ='Week 07'!C3 -> Actual Run Miles | D12: ='Week 07'!C6 -> 0 | E12: Heavy strength + running | H12: Week 07
A13: 8 | B13: 18 | C13: ='Week 08'!C3 -> Actual Run Miles | D13: ='Week 08'!C6 -> 0 | E13: Heavy strength + running | H13: Week 08
A14: 9 | B14: 26 | C14: ='Week 09'!C3 -> Actual Run Miles | D14: ='Week 09'!C6 -> 0 | E14: Heavy strength + running | H14: Week 09
A15: 10 | B15: 28 | C15: ='Week 10'!C3 -> Actual Run Miles | D15: ='Week 10'!C6 -> 0 | E15: Heavy strength + running | H15: Week 10
A16: 11 | B16: 30 | C16: ='Week 11'!C3 -> Actual Run Miles | D16: ='Week 11'!C6 -> 0 | E16: Heavy strength + running | H16: Week 11
A17: 12 | B17: 20 | C17: ='Week 12'!C3 -> Actual Run Miles | D17: ='Week 12'!C6 -> 0 | E17: Heavy strength + running | H17: Week 12

Sheet Maxes
A1: Starting Maxes / Best Sets
A3: Lift / Metric | B3: Provided | C3: Estimated / Notes | D3: Training Approach | E3: Editable? | F3: Notes
A4: Back Squat | B4: 345 x 7 | C4: ~420 e1RM | D4: Heavy progression begins at 315 x 6 sets | E4: Yes | F4: Primary lower strength marker
A5: Deadlift | B5: 500 x 1 | C5: 500 1RM | D5: 405+ early, builds to 485+ singles/doubles | E5: Yes | F5: Managed due to running volume
A6: Bench Press | B6: 325 x 1 | C6: 325 1RM | D6: 255 x 6 early, builds to 315 singles/doubles | E6: Yes | F6: Primary upper strength marker
A7: Overhead Press | B7: 135 x 6 | C7: ~160 e1RM | D7: 115 x 6 early, builds to 155 singles | E7: Yes | F7: Secondary upper strength
A8: Weighted Pull-Up | B8: BW 190 + 30 x 7 | C8: ~268 total e1RM | D8: Added load progresses +30 to +70 | E8: Yes | F8: Relative strength marker
A9: Barbell Row | B9: 225 x 5 | C9: ~258 1RM | D9: 225+ weekly heavy row work | E9: Yes | F9: Upper back strength
A10: 2-Mile Run | B10: 14:00 | C10: Current benchmark | D10: Intervals + tempo + long run progression | E10: Yes | F10: Retest Week 12
A11: Easy Pace | B11: 9:40 / mi | C11: Zone 2 reference | D11: Keep easy days conversational | E11: Yes | F11: Do not race easy runs

Sheet Week 01
A1: Week 01 - Heavy Hybrid Plan | Day-by-Day Log
A3: Planned Run Miles | B3: 16 | C3: Actual Run Miles | E3: Avg Sleep | G3: Stress 1-10 | I3: Bodyweight
A4: Notes
A5: Readiness Formula | B5: =(10-F3)+(10-H3)+IF(F3="",0,F3) -> 20
A6: Weekly Goal | B6: Push heavy but recoverable. No missed reps unless Week 12 testing.
A8: Day 1 - Lower Strength + Easy Run
A9: Category | B9: Exercise / Session | C9: Sets | D9: Reps / Distance | E9: Planned Load / Time / Pace | F9: Target RPE / Zone | G9: Actual Load / Time | H9: Actual Reps / Distance | I9: Actual RPE | J9: Done? | K9: Notes
A10: Strength | B10: Back Squat | C10: 4 x 6 | D10: — | E10: 315 lb | F10: RPE 8-9
A11: Strength | B11: Romanian Deadlift | C11: 4 x 6 | D11: — | E11: 315 lb | F11: RPE 8
A12: Accessory | B12: Bulgarian Split Squat | C12: 3-4 | D12: 8-10/leg | E12: Heavy DBs | F12: RPE 8
A13: Accessory | B13: Seated Leg Curl | C13: 3-4 | D13: 10-12 | E13: Progress weekly | F13: RPE 8
A14: Accessory | B14: Standing Calf Raise | C14: 4 | D14: 8-12 | E14: Heavy | F14: RPE 8
A15: Core | B15: Hanging Leg Raise | C15: 3 | D15: 10-15 | E15: Bodyweight/weighted | F15: RPE 7-8
A16: Run | B16: Easy Zone 2 Run | C16: 1 | D16: 3 mi | E16: Pace 9:20-10:20/mi | F16: Zone 2
A19: Day 2 - Upper Strength + Intervals
A20: Category | B20: Exercise / Session | C20: Sets | D20: Reps / Distance | E20: Planned Load / Time / Pace | F20: Target RPE / Zone | G20: Actual Load / Time | H20: Actual Reps / Distance | I20: Actual RPE | J20: Done? | K20: Notes
A21: Strength | B21: Bench Press | C21: 4 x 6 | D21: — | E21: 255 lb | F21: RPE 8-9
A22: Strength | B22: Weighted Pull-Up | C22: 5 x 5 | D22: — | E22: +30 lb | F22: RPE 8-9
A23: Strength | B23: Overhead Press | C23: 4 x 6 | D23: — | E23: 115 lb | F23: RPE 8
A24: Strength | B24: Barbell Row | C24: 4 x 5 | D24: — | E24: 225 lb | F24: RPE 8
A25: Accessory | B25: Incline DB Press | C25: 3 | D25: 8-10 | E25: Heavy DBs | F25: RPE 8
A26: Accessory | B26: Face Pull | C26: 3 | D26: 12-20 | E26: Cable | F26: RPE 7
A27: Carry | B27: Farmer Carry | C27: 4 | D27: 40-60 m | E27: Heavy | F27: RPE 8
A28: Run | B28: Intervals | C28: 1 | D28: 6 x 400m | E28: Warm-up/cooldown included | F28: RPE 8
A31: Day 3 - Pull Hypertrophy + Tempo Run
A32: Category | B32: Exercise / Session | C32: Sets | D32: Reps / Distance | E32: Planned Load / Time / Pace | F32: Target RPE / Zone | G32: Actual Load / Time | H32: Actual Reps / Distance | I32: Actual RPE | J32: Done? | K32: Notes
A33: Strength | B33: Deadlift | C33: 4 x 4 | D33: — | E33: 405 lb | F33: RPE 8-9
A34: Accessory | B34: Chest-Supported Row | C34: 4 | D34: 8-12 | E34: Progress weekly | F34: RPE 8
A35: Accessory | B35: Lat Pulldown | C35: 4 | D35: 10-12 | E35: Progress weekly | F35: RPE 8
A36: Accessory | B36: Seated Cable Row | C36: 3 | D36: 10-12 | E36: Progress weekly | F36: RPE 8
A37: Accessory | B37: Rear Delt Fly | C37: 4 | D37: 12-20 | E37: Strict | F37: RPE 8
A38: Accessory | B38: DB Curl | C38: 3 | D38: 8-12 | E38: Strict | F38: RPE 8
A39: Accessory | B39: Hammer Curl | C39: 3 | D39: 10-12 | E39: Strict | F39: RPE 8
A40: Run | B40: Tempo Run | C40: 1 | D40: 15 min tempo | E40: Comfortably hard | F40: RPE 7-8
A43: Day 4 - Push Hypertrophy + Low-Impact Cardio
A44: Category | B44: Exercise / Session | C44: Sets | D44: Reps / Distance | E44: Planned Load / Time / Pace | F44: Target RPE / Zone | G44: Actual Load / Time | H44: Actual Reps / Distance | I44: Actual RPE | J44: Done? | K44: Notes
A45: Strength | B45: Incline Bench Press | C45: 4 | D45: 6-8 | E45: 205 lb | F45: RPE 8
A46: Accessory | B46: DB Shoulder Press | C46: 4 | D46: 8-10 | E46: Heavy DBs | F46: RPE 8
A47: Strength | B47: Weighted Dip | C47: 3-4 | D47: 6-10 | E47: +35 lb | F47: RPE 8
A48: Accessory | B48: Cable Fly | C48: 3 | D48: 12-15 | E48: Controlled | F48: RPE 8
...

Sheet Week 02
A1: Week 02 - Heavy Hybrid Plan | Day-by-Day Log
A3: Planned Run Miles | B3: 18 | C3: Actual Run Miles | E3: Avg Sleep | G3: Stress 1-10 | I3: Bodyweight
A4: Notes
A5: Readiness Formula | B5: =(10-F3)+(10-H3)+IF(F3="",0,F3) -> 20
A6: Weekly Goal | B6: Push heavy but recoverable. No missed reps unless Week 12 testing.
A8: Day 1 - Lower Strength + Easy Run
A9: Category | B9: Exercise / Session | C9: Sets | D9: Reps / Distance | E9: Planned Load / Time / Pace | F9: Target RPE / Zone | G9: Actual Load / Time | H9: Actual Reps / Distance | I9: Actual RPE | J9: Done? | K9: Notes
A10: Strength | B10: Back Squat | C10: 5 x 6 | D10: — | E10: 320 lb | F10: RPE 8-9
A11: Strength | B11: Romanian Deadlift | C11: 4 x 6 | D11: — | E11: 335 lb | F11: RPE 8
A12: Accessory | B12: Bulgarian Split Squat | C12: 3-4 | D12: 8-10/leg | E12: Heavy DBs | F12: RPE 8
A13: Accessory | B13: Seated Leg Curl | C13: 3-4 | D13: 10-12 | E13: Progress weekly | F13: RPE 8
A14: Accessory | B14: Standing Calf Raise | C14: 4 | D14: 8-12 | E14: Heavy | F14: RPE 8
A15: Core | B15: Hanging Leg Raise | C15: 3 | D15: 10-15 | E15: Bodyweight/weighted | F15: RPE 7-8
A16: Run | B16: Easy Zone 2 Run | C16: 1 | D16: 3 mi | E16: Pace 9:20-10:20/mi | F16: Zone 2
A19: Day 2 - Upper Strength + Intervals
A20: Category | B20: Exercise / Session | C20: Sets | D20: Reps / Distance | E20: Planned Load / Time / Pace | F20: Target RPE / Zone | G20: Actual Load / Time | H20: Actual Reps / Distance | I20: Actual RPE | J20: Done? | K20: Notes
A21: Strength | B21: Bench Press | C21: 5 x 6 | D21: — | E21: 260 lb | F21: RPE 8-9
A22: Strength | B22: Weighted Pull-Up | C22: 5 x 5 | D22: — | E22: +35 lb | F22: RPE 8-9
A23: Strength | B23: Overhead Press | C23: 5 x 5 | D23: — | E23: 120 lb | F23: RPE 8
A24: Strength | B24: Barbell Row | C24: 5 x 5 | D24: — | E24: 230 lb | F24: RPE 8
A25: Accessory | B25: Incline DB Press | C25: 3 | D25: 8-10 | E25: Heavy DBs | F25: RPE 8
A26: Accessory | B26: Face Pull | C26: 3 | D26: 12-20 | E26: Cable | F26: RPE 7
A27: Carry | B27: Farmer Carry | C27: 4 | D27: 40-60 m | E27: Heavy | F27: RPE 8
A28: Run | B28: Intervals | C28: 1 | D28: 8 x 400m | E28: Warm-up/cooldown included | F28: RPE 8
A31: Day 3 - Pull Hypertrophy + Tempo Run
A32: Category | B32: Exercise / Session | C32: Sets | D32: Reps / Distance | E32: Planned Load / Time / Pace | F32: Target RPE / Zone | G32: Actual Load / Time | H32: Actual Reps / Distance | I32: Actual RPE | J32: Done? | K32: Notes
A33: Strength | B33: Deadlift | C33: 4 x 4 | D33: — | E33: 415 lb | F33: RPE 8-9
A34: Accessory | B34: Chest-Supported Row | C34: 4 | D34: 8-12 | E34: Progress weekly | F34: RPE 8
A35: Accessory | B35: Lat Pulldown | C35: 4 | D35: 10-12 | E35: Progress weekly | F35: RPE 8
A36: Accessory | B36: Seated Cable Row | C36: 3 | D36: 10-12 | E36: Progress weekly | F36: RPE 8
A37: Accessory | B37: Rear Delt Fly | C37: 4 | D37: 12-20 | E37: Strict | F37: RPE 8
A38: Accessory | B38: DB Curl | C38: 3 | D38: 8-12 | E38: Strict | F38: RPE 8
A39: Accessory | B39: Hammer Curl | C39: 3 | D39: 10-12 | E39: Strict | F39: RPE 8
A40: Run | B40: Tempo Run | C40: 1 | D40: 18 min tempo | E40: Comfortably hard | F40: RPE 7-8
A43: Day 4 - Push Hypertrophy + Low-Impact Cardio
A44: Category | B44: Exercise / Session | C44: Sets | D44: Reps / Distance | E44: Planned Load / Time / Pace | F44: Target RPE / Zone | G44: Actual Load / Time | H44: Actual Reps / Distance | I44: Actual RPE | J44: Done? | K44: Notes
A45: Strength | B45: Incline Bench Press | C45: 4 | D45: 6-8 | E45: 210 lb | F45: RPE 8
A46: Accessory | B46: DB Shoulder Press | C46: 4 | D46: 8-10 | E46: Heavy DBs | F46: RPE 8
A47: Strength | B47: Weighted Dip | C47: 3-4 | D47: 6-10 | E47: +40 lb | F47: RPE 8
A48: Accessory | B48: Cable Fly | C48: 3 | D48: 12-15 | E48: Controlled | F48: RPE 8
...

Sheet Week 03
A1: Week 03 - Heavy Hybrid Plan | Day-by-Day Log
A3: Planned Run Miles | B3: 20 | C3: Actual Run Miles | E3: Avg Sleep | G3: Stress 1-10 | I3: Bodyweight
A4: Notes
A5: Readiness Formula | B5: =(10-F3)+(10-H3)+IF(F3="",0,F3) -> 20
A6: Weekly Goal | B6: Push heavy but recoverable. No missed reps unless Week 12 testing.
A8: Day 1 - Lower Strength + Easy Run
A9: Category | B9: Exercise / Session | C9: Sets | D9: Reps / Distance | E9: Planned Load / Time / Pace | F9: Target RPE / Zone | G9: Actual Load / Time | H9: Actual Reps / Distance | I9: Actual RPE | J9: Done? | K9: Notes
A10: Strength | B10: Back Squat | C10: 5 x 6 | D10: — | E10: 325 lb | F10: RPE 8-9
A11: Strength | B11: Romanian Deadlift | C11: 4 x 5 | D11: — | E11: 345 lb | F11: RPE 8
A12: Accessory | B12: Bulgarian Split Squat | C12: 3-4 | D12: 8-10/leg | E12: Heavy DBs | F12: RPE 8
A13: Accessory | B13: Seated Leg Curl | C13: 3-4 | D13: 10-12 | E13: Progress weekly | F13: RPE 8
A14: Accessory | B14: Standing Calf Raise | C14: 4 | D14: 8-12 | E14: Heavy | F14: RPE 8
A15: Core | B15: Hanging Leg Raise | C15: 3 | D15: 10-15 | E15: Bodyweight/weighted | F15: RPE 7-8
A16: Run | B16: Easy Zone 2 Run | C16: 1 | D16: 4 mi | E16: Pace 9:20-10:20/mi | F16: Zone 2
A19: Day 2 - Upper Strength + Intervals
A20: Category | B20: Exercise / Session | C20: Sets | D20: Reps / Distance | E20: Planned Load / Time / Pace | F20: Target RPE / Zone | G20: Actual Load / Time | H20: Actual Reps / Distance | I20: Actual RPE | J20: Done? | K20: Notes
A21: Strength | B21: Bench Press | C21: 5 x 5 | D21: — | E21: 265 lb | F21: RPE 8-9
A22: Strength | B22: Weighted Pull-Up | C22: 5 x 4 | D22: — | E22: +40 lb | F22: RPE 8-9
A23: Strength | B23: Overhead Press | C23: 5 x 5 | D23: — | E23: 125 lb | F23: RPE 8
A24: Strength | B24: Barbell Row | C24: 5 x 4 | D24: — | E24: 235 lb | F24: RPE 8
A25: Accessory | B25: Incline DB Press | C25: 3 | D25: 8-10 | E25: Heavy DBs | F25: RPE 8
A26: Accessory | B26: Face Pull | C26: 3 | D26: 12-20 | E26: Cable | F26: RPE 7
A27: Carry | B27: Farmer Carry | C27: 4 | D27: 40-60 m | E27: Heavy | F27: RPE 8
A28: Run | B28: Intervals | C28: 1 | D28: 5 x 600m | E28: Warm-up/cooldown included | F28: RPE 8
A31: Day 3 - Pull Hypertrophy + Tempo Run
A32: Category | B32: Exercise / Session | C32: Sets | D32: Reps / Distance | E32: Planned Load / Time / Pace | F32: Target RPE / Zone | G32: Actual Load / Time | H32: Actual Reps / Distance | I32: Actual RPE | J32: Done? | K32: Notes
A33: Strength | B33: Deadlift | C33: 5 x 3 | D33: — | E33: 425 lb | F33: RPE 8-9
A34: Accessory | B34: Chest-Supported Row | C34: 4 | D34: 8-12 | E34: Progress weekly | F34: RPE 8
A35: Accessory | B35: Lat Pulldown | C35: 4 | D35: 10-12 | E35: Progress weekly | F35: RPE 8
A36: Accessory | B36: Seated Cable Row | C36: 3 | D36: 10-12 | E36: Progress weekly | F36: RPE 8
A37: Accessory | B37: Rear Delt Fly | C37: 4 | D37: 12-20 | E37: Strict | F37: RPE 8
A38: Accessory | B38: DB Curl | C38: 3 | D38: 8-12 | E38: Strict | F38: RPE 8
A39: Accessory | B39: Hammer Curl | C39: 3 | D39: 10-12 | E39: Strict | F39: RPE 8
A40: Run | B40: Tempo Run | C40: 1 | D40: 20 min tempo | E40: Comfortably hard | F40: RPE 7-8
A43: Day 4 - Push Hypertrophy + Low-Impact Cardio
A44: Category | B44: Exercise / Session | C44: Sets | D44: Reps / Distance | E44: Planned Load / Time / Pace | F44: Target RPE / Zone | G44: Actual Load / Time | H44: Actual Reps / Distance | I44: Actual RPE | J44: Done? | K44: Notes
A45: Strength | B45: Incline Bench Press | C45: 4 | D45: 6-8 | E45: 215 lb | F45: RPE 8
A46: Accessory | B46: DB Shoulder Press | C46: 4 | D46: 8-10 | E46: Heavy DBs | F46: RPE 8
A47: Strength | B47: Weighted Dip | C47: 3-4 | D47: 6-10 | E47: +45 lb | F47: RPE 8
A48: Accessory | B48: Cable Fly | C48: 3 | D48: 12-15 | E48: Controlled | F48: RPE 8
...

Sheet Week 04
A1: Week 04 - Heavy Hybrid Plan | Day-by-Day Log
A3: Planned Run Miles | B3: 15 | C3: Actual Run Miles | E3: Avg Sleep | G3: Stress 1-10 | I3: Bodyweight
A4: Notes
A5: Readiness Formula | B5: =(10-F3)+(10-H3)+IF(F3="",0,F3) -> 20
A6: Weekly Goal | B6: Push heavy but recoverable. No missed reps unless Week 12 testing.
A8: Day 1 - Lower Strength + Easy Run
A9: Category | B9: Exercise / Session | C9: Sets | D9: Reps / Distance | E9: Planned Load / Time / Pace | F9: Target RPE / Zone | G9: Actual Load / Time | H9: Actual Reps / Distance | I9: Actual RPE | J9: Done? | K9: Notes
A10: Strength | B10: Back Squat | C10: 3 x 5 | D10: — | E10: 275 lb deload | F10: RPE 8-9
A11: Strength | B11: Romanian Deadlift | C11: 2 x 6 | D11: — | E11: 255 lb deload | F11: RPE 8
A12: Accessory | B12: Bulgarian Split Squat | C12: 3-4 | D12: 8-10/leg | E12: Heavy DBs | F12: RPE 8
A13: Accessory | B13: Seated Leg Curl | C13: 3-4 | D13: 10-12 | E13: Progress weekly | F13: RPE 8
A14: Accessory | B14: Standing Calf Raise | C14: 4 | D14: 8-12 | E14: Heavy | F14: RPE 8
A15: Core | B15: Hanging Leg Raise | C15: 3 | D15: 10-15 | E15: Bodyweight/weighted | F15: RPE 7-8
A16: Run | B16: Easy Zone 2 Run | C16: 1 | D16: 2-3 mi | E16: Pace 9:20-10:20/mi | F16: Zone 2
A19: Day 2 - Upper Strength + Intervals
A20: Category | B20: Exercise / Session | C20: Sets | D20: Reps / Distance | E20: Planned Load / Time / Pace | F20: Target RPE / Zone | G20: Actual Load / Time | H20: Actual Reps / Distance | I20: Actual RPE | J20: Done? | K20: Notes
A21: Strength | B21: Bench Press | C21: 3 x 5 | D21: — | E21: 205 lb deload | F21: RPE 8-9
A22: Strength | B22: Weighted Pull-Up | C22: 3 x 8 | D22: — | E22: Bodyweight deload | F22: RPE 8-9
A23: Strength | B23: Overhead Press | C23: 3 x 5 | D23: — | E23: 95 lb deload | F23: RPE 8
A24: Strength | B24: Barbell Row | C24: 3 x 6 | D24: — | E24: 185 lb deload | F24: RPE 8
A25: Accessory | B25: Incline DB Press | C25: 3 | D25: 8-10 | E25: Heavy DBs | F25: RPE 8
A26: Accessory | B26: Face Pull | C26: 3 | D26: 12-20 | E26: Cable | F26: RPE 7
A27: Carry | B27: Farmer Carry | C27: 4 | D27: 40-60 m | E27: Heavy | F27: RPE 8
A28: Run | B28: Intervals | C28: 1 | D28: 4 x 400m light | E28: Warm-up/cooldown included | F28: RPE 8
A31: Day 3 - Pull Hypertrophy + Tempo Run
A32: Category | B32: Exercise / Session | C32: Sets | D32: Reps / Distance | E32: Planned Load / Time / Pace | F32: Target RPE / Zone | G32: Actual Load / Time | H32: Actual Reps / Distance | I32: Actual RPE | J32: Done? | K32: Notes
A33: Strength | B33: Deadlift | C33: 3 x 4 | D33: — | E33: 315 lb deload | F33: RPE 8-9
A34: Accessory | B34: Chest-Supported Row | C34: 4 | D34: 8-12 | E34: Progress weekly | F34: RPE 8
A35: Accessory | B35: Lat Pulldown | C35: 4 | D35: 10-12 | E35: Progress weekly | F35: RPE 8
A36: Accessory | B36: Seated Cable Row | C36: 3 | D36: 10-12 | E36: Progress weekly | F36: RPE 8
A37: Accessory | B37: Rear Delt Fly | C37: 4 | D37: 12-20 | E37: Strict | F37: RPE 8
A38: Accessory | B38: DB Curl | C38: 3 | D38: 8-12 | E38: Strict | F38: RPE 8
A39: Accessory | B39: Hammer Curl | C39: 3 | D39: 10-12 | E39: Strict | F39: RPE 8
A40: Run | B40: Tempo Run | C40: 1 | D40: 10-12 min light tempo | E40: Comfortably hard | F40: RPE 7-8
A43: Day 4 - Push Hypertrophy + Low-Impact Cardio
A44: Category | B44: Exercise / Session | C44: Sets | D44: Reps / Distance | E44: Planned Load / Time / Pace | F44: Target RPE / Zone | G44: Actual Load / Time | H44: Actual Reps / Distance | I44: Actual RPE | J44: Done? | K44: Notes
A45: Strength | B45: Incline Bench Press | C45: 4 | D45: 6-8 | E45: 175 lb deload | F45: RPE 8
A46: Accessory | B46: DB Shoulder Press | C46: 4 | D46: 8-10 | E46: Heavy DBs | F46: RPE 8
A47: Strength | B47: Weighted Dip | C47: 3-4 | D47: 6-10 | E47: BW deload | F47: RPE 8
A48: Accessory | B48: Cable Fly | C48: 3 | D48: 12-15 | E48: Controlled | F48: RPE 8
...

Sheet Week 05
A1: Week 05 - Heavy Hybrid Plan | Day-by-Day Log
A3: Planned Run Miles | B3: 21 | C3: Actual Run Miles | E3: Avg Sleep | G3: Stress 1-10 | I3: Bodyweight
A4: Notes
A5: Readiness Formula | B5: =(10-F3)+(10-H3)+IF(F3="",0,F3) -> 20
A6: Weekly Goal | B6: Push heavy but recoverable. No missed reps unless Week 12 testing.
A8: Day 1 - Lower Strength + Easy Run
A9: Category | B9: Exercise / Session | C9: Sets | D9: Reps / Distance | E9: Planned Load / Time / Pace | F9: Target RPE / Zone | G9: Actual Load / Time | H9: Actual Reps / Distance | I9: Actual RPE | J9: Done? | K9: Notes
A10: Strength | B10: Back Squat | C10: 5 x 5 | D10: — | E10: 335 lb | F10: RPE 8-9
A11: Strength | B11: Romanian Deadlift | C11: 4 x 5 | D11: — | E11: 355 lb | F11: RPE 8
A12: Accessory | B12: Bulgarian Split Squat | C12: 3-4 | D12: 8-10/leg | E12: Heavy DBs | F12: RPE 8
A13: Accessory | B13: Seated Leg Curl | C13: 3-4 | D13: 10-12 | E13: Progress weekly | F13: RPE 8
A14: Accessory | B14: Standing Calf Raise | C14: 4 | D14: 8-12 | E14: Heavy | F14: RPE 8
A15: Core | B15: Hanging Leg Raise | C15: 3 | D15: 10-15 | E15: Bodyweight/weighted | F15: RPE 7-8
A16: Run | B16: Easy Zone 2 Run | C16: 1 | D16: 4 mi | E16: Pace 9:20-10:20/mi | F16: Zone 2
A19: Day 2 - Upper Strength + Intervals
A20: Category | B20: Exercise / Session | C20: Sets | D20: Reps / Distance | E20: Planned Load / Time / Pace | F20: Target RPE / Zone | G20: Actual Load / Time | H20: Actual Reps / Distance | I20: Actual RPE | J20: Done? | K20: Notes
A21: Strength | B21: Bench Press | C21: 5 x 4 | D21: — | E21: 275 lb | F21: RPE 8-9
A22: Strength | B22: Weighted Pull-Up | C22: 5 x 4 | D22: — | E22: +45 lb | F22: RPE 8-9
A23: Strength | B23: Overhead Press | C23: 5 x 4 | D23: — | E23: 130 lb | F23: RPE 8
A24: Strength | B24: Barbell Row | C24: 5 x 4 | D24: — | E24: 240 lb | F24: RPE 8
A25: Accessory | B25: Incline DB Press | C25: 3 | D25: 8-10 | E25: Heavy DBs | F25: RPE 8
A26: Accessory | B26: Face Pull | C26: 3 | D26: 12-20 | E26: Cable | F26: RPE 7
A27: Carry | B27: Farmer Carry | C27: 4 | D27: 40-60 m | E27: Heavy | F27: RPE 8
A28: Run | B28: Intervals | C28: 1 | D28: 6 x 600m | E28: Warm-up/cooldown included | F28: RPE 8
A31: Day 3 - Pull Hypertrophy + Tempo Run
A32: Category | B32: Exercise / Session | C32: Sets | D32: Reps / Distance | E32: Planned Load / Time / Pace | F32: Target RPE / Zone | G32: Actual Load / Time | H32: Actual Reps / Distance | I32: Actual RPE | J32: Done? | K32: Notes
A33: Strength | B33: Deadlift | C33: 5 x 3 | D33: — | E33: 435 lb | F33: RPE 8-9
A34: Accessory | B34: Chest-Supported Row | C34: 4 | D34: 8-12 | E34: Progress weekly | F34: RPE 8
A35: Accessory | B35: Lat Pulldown | C35: 4 | D35: 10-12 | E35: Progress weekly | F35: RPE 8
A36: Accessory | B36: Seated Cable Row | C36: 3 | D36: 10-12 | E36: Progress weekly | F36: RPE 8
A37: Accessory | B37: Rear Delt Fly | C37: 4 | D37: 12-20 | E37: Strict | F37: RPE 8
A38: Accessory | B38: DB Curl | C38: 3 | D38: 8-12 | E38: Strict | F38: RPE 8
A39: Accessory | B39: Hammer Curl | C39: 3 | D39: 10-12 | E39: Strict | F39: RPE 8
A40: Run | B40: Tempo Run | C40: 1 | D40: 22 min tempo | E40: Comfortably hard | F40: RPE 7-8
A43: Day 4 - Push Hypertrophy + Low-Impact Cardio
A44: Category | B44: Exercise / Session | C44: Sets | D44: Reps / Distance | E44: Planned Load / Time / Pace | F44: Target RPE / Zone | G44: Actual Load / Time | H44: Actual Reps / Distance | I44: Actual RPE | J44: Done? | K44: Notes
A45: Strength | B45: Incline Bench Press | C45: 4 | D45: 6-8 | E45: 220 lb | F45: RPE 8
A46: Accessory | B46: DB Shoulder Press | C46: 4 | D46: 8-10 | E46: Heavy DBs | F46: RPE 8
A47: Strength | B47: Weighted Dip | C47: 3-4 | D47: 6-10 | E47: +50 lb | F47: RPE 8
A48: Accessory | B48: Cable Fly | C48: 3 | D48: 12-15 | E48: Controlled | F48: RPE 8
...

Sheet Week 06
A1: Week 06 - Heavy Hybrid Plan | Day-by-Day Log
A3: Planned Run Miles | B3: 23 | C3: Actual Run Miles | E3: Avg Sleep | G3: Stress 1-10 | I3: Bodyweight
A4: Notes
A5: Readiness Formula | B5: =(10-F3)+(10-H3)+IF(F3="",0,F3) -> 20
A6: Weekly Goal | B6: Push heavy but recoverable. No missed reps unless Week 12 testing.
A8: Day 1 - Lower Strength + Easy Run
A9: Category | B9: Exercise / Session | C9: Sets | D9: Reps / Distance | E9: Planned Load / Time / Pace | F9: Target RPE / Zone | G9: Actual Load / Time | H9: Actual Reps / Distance | I9: Actual RPE | J9: Done? | K9: Notes
A10: Strength | B10: Back Squat | C10: 5 x 5 | D10: — | E10: 345 lb | F10: RPE 8-9
A11: Strength | B11: Romanian Deadlift | C11: 4 x 4 | D11: — | E11: 365 lb | F11: RPE 8
A12: Accessory | B12: Bulgarian Split Squat | C12: 3-4 | D12: 8-10/leg | E12: Heavy DBs | F12: RPE 8
A13: Accessory | B13: Seated Leg Curl | C13: 3-4 | D13: 10-12 | E13: Progress weekly | F13: RPE 8
A14: Accessory | B14: Standing Calf Raise | C14: 4 | D14: 8-12 | E14: Heavy | F14: RPE 8
A15: Core | B15: Hanging Leg Raise | C15: 3 | D15: 10-15 | E15: Bodyweight/weighted | F15: RPE 7-8
A16: Run | B16: Easy Zone 2 Run | C16: 1 | D16: 4 mi | E16: Pace 9:20-10:20/mi | F16: Zone 2
A19: Day 2 - Upper Strength + Intervals
A20: Category | B20: Exercise / Session | C20: Sets | D20: Reps / Distance | E20: Planned Load / Time / Pace | F20: Target RPE / Zone | G20: Actual Load / Time | H20: Actual Reps / Distance | I20: Actual RPE | J20: Done? | K20: Notes
A21: Strength | B21: Bench Press | C21: 5 x 3 | D21: — | E21: 285 lb | F21: RPE 8-9
A22: Strength | B22: Weighted Pull-Up | C22: 5 x 3 | D22: — | E22: +50 lb | F22: RPE 8-9
A23: Strength | B23: Overhead Press | C23: 5 x 3 | D23: — | E23: 135 lb | F23: RPE 8
A24: Strength | B24: Barbell Row | C24: 5 x 3-4 | D24: — | E24: 245 lb | F24: RPE 8
A25: Accessory | B25: Incline DB Press | C25: 3 | D25: 8-10 | E25: Heavy DBs | F25: RPE 8
A26: Accessory | B26: Face Pull | C26: 3 | D26: 12-20 | E26: Cable | F26: RPE 7
A27: Carry | B27: Farmer Carry | C27: 4 | D27: 40-60 m | E27: Heavy | F27: RPE 8
A28: Run | B28: Intervals | C28: 1 | D28: 4 x 800m | E28: Warm-up/cooldown included | F28: RPE 8
A31: Day 3 - Pull Hypertrophy + Tempo Run
A32: Category | B32: Exercise / Session | C32: Sets | D32: Reps / Distance | E32: Planned Load / Time / Pace | F32: Target RPE / Zone | G32: Actual Load / Time | H32: Actual Reps / Distance | I32: Actual RPE | J32: Done? | K32: Notes
A33: Strength | B33: Deadlift | C33: 5 x 2-3 | D33: — | E33: 445 lb | F33: RPE 8-9
A34: Accessory | B34: Chest-Supported Row | C34: 4 | D34: 8-12 | E34: Progress weekly | F34: RPE 8
A35: Accessory | B35: Lat Pulldown | C35: 4 | D35: 10-12 | E35: Progress weekly | F35: RPE 8
A36: Accessory | B36: Seated Cable Row | C36: 3 | D36: 10-12 | E36: Progress weekly | F36: RPE 8
A37: Accessory | B37: Rear Delt Fly | C37: 4 | D37: 12-20 | E37: Strict | F37: RPE 8
A38: Accessory | B38: DB Curl | C38: 3 | D38: 8-12 | E38: Strict | F38: RPE 8
A39: Accessory | B39: Hammer Curl | C39: 3 | D39: 10-12 | E39: Strict | F39: RPE 8
A40: Run | B40: Tempo Run | C40: 1 | D40: 2 x 12 min tempo | E40: Comfortably hard | F40: RPE 7-8
A43: Day 4 - Push Hypertrophy + Low-Impact Cardio
A44: Category | B44: Exercise / Session | C44: Sets | D44: Reps / Distance | E44: Planned Load / Time / Pace | F44: Target RPE / Zone | G44: Actual Load / Time | H44: Actual Reps / Distance | I44: Actual RPE | J44: Done? | K44: Notes
A45: Strength | B45: Incline Bench Press | C45: 4 | D45: 6-8 | E45: 225 lb | F45: RPE 8
A46: Accessory | B46: DB Shoulder Press | C46: 4 | D46: 8-10 | E46: Heavy DBs | F46: RPE 8
A47: Strength | B47: Weighted Dip | C47: 3-4 | D47: 6-10 | E47: +55 lb | F47: RPE 8
A48: Accessory | B48: Cable Fly | C48: 3 | D48: 12-15 | E48: Controlled | F48: RPE 8
...

Sheet Week 07
A1: Week 07 - Heavy Hybrid Plan | Day-by-Day Log
A3: Planned Run Miles | B3: 25 | C3: Actual Run Miles | E3: Avg Sleep | G3: Stress 1-10 | I3: Bodyweight
A4: Notes
A5: Readiness Formula | B5: =(10-F3)+(10-H3)+IF(F3="",0,F3) -> 20
A6: Weekly Goal | B6: Push heavy but recoverable. No missed reps unless Week 12 testing.
A8: Day 1 - Lower Strength + Easy Run
A9: Category | B9: Exercise / Session | C9: Sets | D9: Reps / Distance | E9: Planned Load / Time / Pace | F9: Target RPE / Zone | G9: Actual Load / Time | H9: Actual Reps / Distance | I9: Actual RPE | J9: Done? | K9: Notes
A10: Strength | B10: Back Squat | C10: 6 x 4 | D10: — | E10: 355 lb | F10: RPE 8-9
A11: Strength | B11: Romanian Deadlift | C11: 4 x 4 | D11: — | E11: 375 lb | F11: RPE 8
A12: Accessory | B12: Bulgarian Split Squat | C12: 3-4 | D12: 8-10/leg | E12: Heavy DBs | F12: RPE 8
A13: Accessory | B13: Seated Leg Curl | C13: 3-4 | D13: 10-12 | E13: Progress weekly | F13: RPE 8
A14: Accessory | B14: Standing Calf Raise | C14: 4 | D14: 8-12 | E14: Heavy | F14: RPE 8
A15: Core | B15: Hanging Leg Raise | C15: 3 | D15: 10-15 | E15: Bodyweight/weighted | F15: RPE 7-8
A16: Run | B16: Easy Zone 2 Run | C16: 1 | D16: 5 mi | E16: Pace 9:20-10:20/mi | F16: Zone 2
A19: Day 2 - Upper Strength + Intervals
A20: Category | B20: Exercise / Session | C20: Sets | D20: Reps / Distance | E20: Planned Load / Time / Pace | F20: Target RPE / Zone | G20: Actual Load / Time | H20: Actual Reps / Distance | I20: Actual RPE | J20: Done? | K20: Notes
A21: Strength | B21: Bench Press | C21: 6 x 3 | D21: — | E21: 295 lb | F21: RPE 8-9
A22: Strength | B22: Weighted Pull-Up | C22: 6 x 3 | D22: — | E22: +55 lb | F22: RPE 8-9
A23: Strength | B23: Overhead Press | C23: 6 x 2-3 | D23: — | E23: 140 lb | F23: RPE 8
A24: Strength | B24: Barbell Row | C24: 6 x 3 | D24: — | E24: 250 lb | F24: RPE 8
A25: Accessory | B25: Incline DB Press | C25: 3 | D25: 8-10 | E25: Heavy DBs | F25: RPE 8
A26: Accessory | B26: Face Pull | C26: 3 | D26: 12-20 | E26: Cable | F26: RPE 7
A27: Carry | B27: Farmer Carry | C27: 4 | D27: 40-60 m | E27: Heavy | F27: RPE 8
A28: Run | B28: Intervals | C28: 1 | D28: 5 x 800m | E28: Warm-up/cooldown included | F28: RPE 8
A31: Day 3 - Pull Hypertrophy + Tempo Run
A32: Category | B32: Exercise / Session | C32: Sets | D32: Reps / Distance | E32: Planned Load / Time / Pace | F32: Target RPE / Zone | G32: Actual Load / Time | H32: Actual Reps / Distance | I32: Actual RPE | J32: Done? | K32: Notes
A33: Strength | B33: Deadlift | C33: 6 x 2 | D33: — | E33: 455 lb | F33: RPE 8-9
A34: Accessory | B34: Chest-Supported Row | C34: 4 | D34: 8-12 | E34: Progress weekly | F34: RPE 8
A35: Accessory | B35: Lat Pulldown | C35: 4 | D35: 10-12 | E35: Progress weekly | F35: RPE 8
A36: Accessory | B36: Seated Cable Row | C36: 3 | D36: 10-12 | E36: Progress weekly | F36: RPE 8
A37: Accessory | B37: Rear Delt Fly | C37: 4 | D37: 12-20 | E37: Strict | F37: RPE 8
A38: Accessory | B38: DB Curl | C38: 3 | D38: 8-12 | E38: Strict | F38: RPE 8
A39: Accessory | B39: Hammer Curl | C39: 3 | D39: 10-12 | E39: Strict | F39: RPE 8
A40: Run | B40: Tempo Run | C40: 1 | D40: 25 min tempo | E40: Comfortably hard | F40: RPE 7-8
A43: Day 4 - Push Hypertrophy + Low-Impact Cardio
A44: Category | B44: Exercise / Session | C44: Sets | D44: Reps / Distance | E44: Planned Load / Time / Pace | F44: Target RPE / Zone | G44: Actual Load / Time | H44: Actual Reps / Distance | I44: Actual RPE | J44: Done? | K44: Notes
A45: Strength | B45: Incline Bench Press | C45: 4 | D45: 6-8 | E45: 230 lb | F45: RPE 8
A46: Accessory | B46: DB Shoulder Press | C46: 4 | D46: 8-10 | E46: Heavy DBs | F46: RPE 8
A47: Strength | B47: Weighted Dip | C47: 3-4 | D47: 6-10 | E47: +60 lb | F47: RPE 8
A48: Accessory | B48: Cable Fly | C48: 3 | D48: 12-15 | E48: Controlled | F48: RPE 8
...

Sheet Week 08
A1: Week 08 - Heavy Hybrid Plan | Day-by-Day Log
A3: Planned Run Miles | B3: 18 | C3: Actual Run Miles | E3: Avg Sleep | G3: Stress 1-10 | I3: Bodyweight
A4: Notes
A5: Readiness Formula | B5: =(10-F3)+(10-H3)+IF(F3="",0,F3) -> 20
A6: Weekly Goal | B6: Push heavy but recoverable. No missed reps unless Week 12 testing.
A8: Day 1 - Lower Strength + Easy Run
A9: Category | B9: Exercise / Session | C9: Sets | D9: Reps / Distance | E9: Planned Load / Time / Pace | F9: Target RPE / Zone | G9: Actual Load / Time | H9: Actual Reps / Distance | I9: Actual RPE | J9: Done? | K9: Notes
A10: Strength | B10: Back Squat | C10: 3 x 5 | D10: — | E10: 295 lb deload | F10: RPE 8-9
A11: Strength | B11: Romanian Deadlift | C11: 2 x 5 | D11: — | E11: 275 lb deload | F11: RPE 8
A12: Accessory | B12: Bulgarian Split Squat | C12: 3-4 | D12: 8-10/leg | E12: Heavy DBs | F12: RPE 8
A13: Accessory | B13: Seated Leg Curl | C13: 3-4 | D13: 10-12 | E13: Progress weekly | F13: RPE 8
A14: Accessory | B14: Standing Calf Raise | C14: 4 | D14: 8-12 | E14: Heavy | F14: RPE 8
A15: Core | B15: Hanging Leg Raise | C15: 3 | D15: 10-15 | E15: Bodyweight/weighted | F15: RPE 7-8
A16: Run | B16: Easy Zone 2 Run | C16: 1 | D16: 3 mi | E16: Pace 9:20-10:20/mi | F16: Zone 2
A19: Day 2 - Upper Strength + Intervals
A20: Category | B20: Exercise / Session | C20: Sets | D20: Reps / Distance | E20: Planned Load / Time / Pace | F20: Target RPE / Zone | G20: Actual Load / Time | H20: Actual Reps / Distance | I20: Actual RPE | J20: Done? | K20: Notes
A21: Strength | B21: Bench Press | C21: 3 x 5 | D21: — | E21: 225 lb deload | F21: RPE 8-9
A22: Strength | B22: Weighted Pull-Up | C22: 3 x 5 | D22: — | E22: +25 lb deload | F22: RPE 8-9
A23: Strength | B23: Overhead Press | C23: 3 x 5 | D23: — | E23: 105 lb deload | F23: RPE 8
A24: Strength | B24: Barbell Row | C24: 3 x 5 | D24: — | E24: 195 lb deload | F24: RPE 8
A25: Accessory | B25: Incline DB Press | C25: 3 | D25: 8-10 | E25: Heavy DBs | F25: RPE 8
A26: Accessory | B26: Face Pull | C26: 3 | D26: 12-20 | E26: Cable | F26: RPE 7
A27: Carry | B27: Farmer Carry | C27: 4 | D27: 40-60 m | E27: Heavy | F27: RPE 8
A28: Run | B28: Intervals | C28: 1 | D28: 5 x 400m light | E28: Warm-up/cooldown included | F28: RPE 8
A31: Day 3 - Pull Hypertrophy + Tempo Run
A32: Category | B32: Exercise / Session | C32: Sets | D32: Reps / Distance | E32: Planned Load / Time / Pace | F32: Target RPE / Zone | G32: Actual Load / Time | H32: Actual Reps / Distance | I32: Actual RPE | J32: Done? | K32: Notes
A33: Strength | B33: Deadlift | C33: 3 x 3 | D33: — | E33: 335 lb deload | F33: RPE 8-9
A34: Accessory | B34: Chest-Supported Row | C34: 4 | D34: 8-12 | E34: Progress weekly | F34: RPE 8
A35: Accessory | B35: Lat Pulldown | C35: 4 | D35: 10-12 | E35: Progress weekly | F35: RPE 8
A36: Accessory | B36: Seated Cable Row | C36: 3 | D36: 10-12 | E36: Progress weekly | F36: RPE 8
A37: Accessory | B37: Rear Delt Fly | C37: 4 | D37: 12-20 | E37: Strict | F37: RPE 8
A38: Accessory | B38: DB Curl | C38: 3 | D38: 8-12 | E38: Strict | F38: RPE 8
A39: Accessory | B39: Hammer Curl | C39: 3 | D39: 10-12 | E39: Strict | F39: RPE 8
A40: Run | B40: Tempo Run | C40: 1 | D40: 12-15 min light tempo | E40: Comfortably hard | F40: RPE 7-8
A43: Day 4 - Push Hypertrophy + Low-Impact Cardio
A44: Category | B44: Exercise / Session | C44: Sets | D44: Reps / Distance | E44: Planned Load / Time / Pace | F44: Target RPE / Zone | G44: Actual Load / Time | H44: Actual Reps / Distance | I44: Actual RPE | J44: Done? | K44: Notes
A45: Strength | B45: Incline Bench Press | C45: 4 | D45: 6-8 | E45: 185 lb deload | F45: RPE 8
A46: Accessory | B46: DB Shoulder Press | C46: 4 | D46: 8-10 | E46: Heavy DBs | F46: RPE 8
A47: Strength | B47: Weighted Dip | C47: 3-4 | D47: 6-10 | E47: +25 lb deload | F47: RPE 8
A48: Accessory | B48: Cable Fly | C48: 3 | D48: 12-15 | E48: Controlled | F48: RPE 8
...

Sheet Week 09
A1: Week 09 - Heavy Hybrid Plan | Day-by-Day Log
A3: Planned Run Miles | B3: 26 | C3: Actual Run Miles | E3: Avg Sleep | G3: Stress 1-10 | I3: Bodyweight
A4: Notes
A5: Readiness Formula | B5: =(10-F3)+(10-H3)+IF(F3="",0,F3) -> 20
A6: Weekly Goal | B6: Push heavy but recoverable. No missed reps unless Week 12 testing.
A8: Day 1 - Lower Strength + Easy Run
A9: Category | B9: Exercise / Session | C9: Sets | D9: Reps / Distance | E9: Planned Load / Time / Pace | F9: Target RPE / Zone | G9: Actual Load / Time | H9: Actual Reps / Distance | I9: Actual RPE | J9: Done? | K9: Notes
A10: Strength | B10: Back Squat | C10: 5 x 3 + 2 x 6 | D10: — | E10: 365 lb + 315 lb back-off | F10: RPE 8-9
A11: Strength | B11: Romanian Deadlift | C11: 4 x 3-4 | D11: — | E11: 385 lb | F11: RPE 8
A12: Accessory | B12: Bulgarian Split Squat | C12: 3-4 | D12: 8-10/leg | E12: Heavy DBs | F12: RPE 8
A13: Accessory | B13: Seated Leg Curl | C13: 3-4 | D13: 10-12 | E13: Progress weekly | F13: RPE 8
A14: Accessory | B14: Standing Calf Raise | C14: 4 | D14: 8-12 | E14: Heavy | F14: RPE 8
A15: Core | B15: Hanging Leg Raise | C15: 3 | D15: 10-15 | E15: Bodyweight/weighted | F15: RPE 7-8
A16: Run | B16: Easy Zone 2 Run | C16: 1 | D16: 5 mi | E16: Pace 9:20-10:20/mi | F16: Zone 2
A19: Day 2 - Upper Strength + Intervals
A20: Category | B20: Exercise / Session | C20: Sets | D20: Reps / Distance | E20: Planned Load / Time / Pace | F20: Target RPE / Zone | G20: Actual Load / Time | H20: Actual Reps / Distance | I20: Actual RPE | J20: Done? | K20: Notes
A21: Strength | B21: Bench Press | C21: 5 x 2 | D21: — | E21: 300 lb | F21: RPE 8-9
A22: Strength | B22: Weighted Pull-Up | C22: 5 x 2 | D22: — | E22: +60 lb | F22: RPE 8-9
A23: Strength | B23: Overhead Press | C23: 5 x 2 | D23: — | E23: 145 lb | F23: RPE 8
A24: Strength | B24: Barbell Row | C24: 5 x 3 | D24: — | E24: 255 lb | F24: RPE 8
A25: Accessory | B25: Incline DB Press | C25: 3 | D25: 8-10 | E25: Heavy DBs | F25: RPE 8
A26: Accessory | B26: Face Pull | C26: 3 | D26: 12-20 | E26: Cable | F26: RPE 7
A27: Carry | B27: Farmer Carry | C27: 4 | D27: 40-60 m | E27: Heavy | F27: RPE 8
A28: Run | B28: Intervals | C28: 1 | D28: 3 x 1000m | E28: Warm-up/cooldown included | F28: RPE 8
A31: Day 3 - Pull Hypertrophy + Tempo Run
A32: Category | B32: Exercise / Session | C32: Sets | D32: Reps / Distance | E32: Planned Load / Time / Pace | F32: Target RPE / Zone | G32: Actual Load / Time | H32: Actual Reps / Distance | I32: Actual RPE | J32: Done? | K32: Notes
A33: Strength | B33: Deadlift | C33: 5 x 2 | D33: — | E33: 465 lb | F33: RPE 8-9
A34: Accessory | B34: Chest-Supported Row | C34: 4 | D34: 8-12 | E34: Progress weekly | F34: RPE 8
A35: Accessory | B35: Lat Pulldown | C35: 4 | D35: 10-12 | E35: Progress weekly | F35: RPE 8
A36: Accessory | B36: Seated Cable Row | C36: 3 | D36: 10-12 | E36: Progress weekly | F36: RPE 8
A37: Accessory | B37: Rear Delt Fly | C37: 4 | D37: 12-20 | E37: Strict | F37: RPE 8
A38: Accessory | B38: DB Curl | C38: 3 | D38: 8-12 | E38: Strict | F38: RPE 8
A39: Accessory | B39: Hammer Curl | C39: 3 | D39: 10-12 | E39: Strict | F39: RPE 8
A40: Run | B40: Tempo Run | C40: 1 | D40: 2 x 15 min tempo | E40: Comfortably hard | F40: RPE 7-8
A43: Day 4 - Push Hypertrophy + Low-Impact Cardio
A44: Category | B44: Exercise / Session | C44: Sets | D44: Reps / Distance | E44: Planned Load / Time / Pace | F44: Target RPE / Zone | G44: Actual Load / Time | H44: Actual Reps / Distance | I44: Actual RPE | J44: Done? | K44: Notes
A45: Strength | B45: Incline Bench Press | C45: 4 | D45: 6-8 | E45: 235 lb | F45: RPE 8
A46: Accessory | B46: DB Shoulder Press | C46: 4 | D46: 8-10 | E46: Heavy DBs | F46: RPE 8
A47: Strength | B47: Weighted Dip | C47: 3-4 | D47: 6-10 | E47: +65 lb | F47: RPE 8
A48: Accessory | B48: Cable Fly | C48: 3 | D48: 12-15 | E48: Controlled | F48: RPE 8
...

Sheet Week 10
A1: Week 10 - Heavy Hybrid Plan | Day-by-Day Log
A3: Planned Run Miles | B3: 28 | C3: Actual Run Miles | E3: Avg Sleep | G3: Stress 1-10 | I3: Bodyweight
A4: Notes
A5: Readiness Formula | B5: =(10-F3)+(10-H3)+IF(F3="",0,F3) -> 20
A6: Weekly Goal | B6: Push heavy but recoverable. No missed reps unless Week 12 testing.
A8: Day 1 - Lower Strength + Easy Run
A9: Category | B9: Exercise / Session | C9: Sets | D9: Reps / Distance | E9: Planned Load / Time / Pace | F9: Target RPE / Zone | G9: Actual Load / Time | H9: Actual Reps / Distance | I9: Actual RPE | J9: Done? | K9: Notes
A10: Strength | B10: Back Squat | C10: 5 x 3 + 2 x 5 | D10: — | E10: 375 lb + 325 lb back-off | F10: RPE 8-9
A11: Strength | B11: Romanian Deadlift | C11: 3 x 3-4 | D11: — | E11: 395 lb | F11: RPE 8
A12: Accessory | B12: Bulgarian Split Squat | C12: 3-4 | D12: 8-10/leg | E12: Heavy DBs | F12: RPE 8
A13: Accessory | B13: Seated Leg Curl | C13: 3-4 | D13: 10-12 | E13: Progress weekly | F13: RPE 8
A14: Accessory | B14: Standing Calf Raise | C14: 4 | D14: 8-12 | E14: Heavy | F14: RPE 8
A15: Core | B15: Hanging Leg Raise | C15: 3 | D15: 10-15 | E15: Bodyweight/weighted | F15: RPE 7-8
A16: Run | B16: Easy Zone 2 Run | C16: 1 | D16: 5 mi | E16: Pace 9:20-10:20/mi | F16: Zone 2
A19: Day 2 - Upper Strength + Intervals
A20: Category | B20: Exercise / Session | C20: Sets | D20: Reps / Distance | E20: Planned Load / Time / Pace | F20: Target RPE / Zone | G20: Actual Load / Time | H20: Actual Reps / Distance | I20: Actual RPE | J20: Done? | K20: Notes
A21: Strength | B21: Bench Press | C21: 4 x 2 | D21: — | E21: 305 lb | F21: RPE 8-9
A22: Strength | B22: Weighted Pull-Up | C22: 4 x 2 | D22: — | E22: +65 lb | F22: RPE 8-9
A23: Strength | B23: Overhead Press | C23: 4 x 1-2 | D23: — | E23: 150 lb | F23: RPE 8
A24: Strength | B24: Barbell Row | C24: 4 x 3 | D24: — | E24: 260 lb | F24: RPE 8
A25: Accessory | B25: Incline DB Press | C25: 3 | D25: 8-10 | E25: Heavy DBs | F25: RPE 8
A26: Accessory | B26: Face Pull | C26: 3 | D26: 12-20 | E26: Cable | F26: RPE 7
A27: Carry | B27: Farmer Carry | C27: 4 | D27: 40-60 m | E27: Heavy | F27: RPE 8
A28: Run | B28: Intervals | C28: 1 | D28: 4 x 1000m | E28: Warm-up/cooldown included | F28: RPE 8
A31: Day 3 - Pull Hypertrophy + Tempo Run
A32: Category | B32: Exercise / Session | C32: Sets | D32: Reps / Distance | E32: Planned Load / Time / Pace | F32: Target RPE / Zone | G32: Actual Load / Time | H32: Actual Reps / Distance | I32: Actual RPE | J32: Done? | K32: Notes
A33: Strength | B33: Deadlift | C33: 4 x 2 | D33: — | E33: 475 lb | F33: RPE 8-9
A34: Accessory | B34: Chest-Supported Row | C34: 4 | D34: 8-12 | E34: Progress weekly | F34: RPE 8
A35: Accessory | B35: Lat Pulldown | C35: 4 | D35: 10-12 | E35: Progress weekly | F35: RPE 8
A36: Accessory | B36: Seated Cable Row | C36: 3 | D36: 10-12 | E36: Progress weekly | F36: RPE 8
A37: Accessory | B37: Rear Delt Fly | C37: 4 | D37: 12-20 | E37: Strict | F37: RPE 8
A38: Accessory | B38: DB Curl | C38: 3 | D38: 8-12 | E38: Strict | F38: RPE 8
A39: Accessory | B39: Hammer Curl | C39: 3 | D39: 10-12 | E39: Strict | F39: RPE 8
A40: Run | B40: Tempo Run | C40: 1 | D40: 30 min tempo | E40: Comfortably hard | F40: RPE 7-8
A43: Day 4 - Push Hypertrophy + Low-Impact Cardio
A44: Category | B44: Exercise / Session | C44: Sets | D44: Reps / Distance | E44: Planned Load / Time / Pace | F44: Target RPE / Zone | G44: Actual Load / Time | H44: Actual Reps / Distance | I44: Actual RPE | J44: Done? | K44: Notes
A45: Strength | B45: Incline Bench Press | C45: 4 | D45: 6-8 | E45: 240 lb | F45: RPE 8
A46: Accessory | B46: DB Shoulder Press | C46: 4 | D46: 8-10 | E46: Heavy DBs | F46: RPE 8
A47: Strength | B47: Weighted Dip | C47: 3-4 | D47: 6-10 | E47: +70 lb | F47: RPE 8
A48: Accessory | B48: Cable Fly | C48: 3 | D48: 12-15 | E48: Controlled | F48: RPE 8
...

Sheet Week 11
A1: Week 11 - Heavy Hybrid Plan | Day-by-Day Log
A3: Planned Run Miles | B3: 30 | C3: Actual Run Miles | E3: Avg Sleep | G3: Stress 1-10 | I3: Bodyweight
A4: Notes
A5: Readiness Formula | B5: =(10-F3)+(10-H3)+IF(F3="",0,F3) -> 20
A6: Weekly Goal | B6: Push heavy but recoverable. No missed reps unless Week 12 testing.
A8: Day 1 - Lower Strength + Easy Run
A9: Category | B9: Exercise / Session | C9: Sets | D9: Reps / Distance | E9: Planned Load / Time / Pace | F9: Target RPE / Zone | G9: Actual Load / Time | H9: Actual Reps / Distance | I9: Actual RPE | J9: Done? | K9: Notes
A10: Strength | B10: Back Squat | C10: 4 x 2 + 2 x 4 | D10: — | E10: 385 lb + 335 lb back-off | F10: RPE 8-9
A11: Strength | B11: Romanian Deadlift | C11: 3 x 3 | D11: — | E11: 405 lb | F11: RPE 8
A12: Accessory | B12: Bulgarian Split Squat | C12: 3-4 | D12: 8-10/leg | E12: Heavy DBs | F12: RPE 8
A13: Accessory | B13: Seated Leg Curl | C13: 3-4 | D13: 10-12 | E13: Progress weekly | F13: RPE 8
A14: Accessory | B14: Standing Calf Raise | C14: 4 | D14: 8-12 | E14: Heavy | F14: RPE 8
A15: Core | B15: Hanging Leg Raise | C15: 3 | D15: 10-15 | E15: Bodyweight/weighted | F15: RPE 7-8
A16: Run | B16: Easy Zone 2 Run | C16: 1 | D16: 6 mi | E16: Pace 9:20-10:20/mi | F16: Zone 2
A19: Day 2 - Upper Strength + Intervals
A20: Category | B20: Exercise / Session | C20: Sets | D20: Reps / Distance | E20: Planned Load / Time / Pace | F20: Target RPE / Zone | G20: Actual Load / Time | H20: Actual Reps / Distance | I20: Actual RPE | J20: Done? | K20: Notes
A21: Strength | B21: Bench Press | C21: 3 x 1-2 | D21: — | E21: 315 lb | F21: RPE 8-9
A22: Strength | B22: Weighted Pull-Up | C22: 3 x 1-2 | D22: — | E22: +70 lb | F22: RPE 8-9
A23: Strength | B23: Overhead Press | C23: 3 x 1 | D23: — | E23: 155 lb | F23: RPE 8
A24: Strength | B24: Barbell Row | C24: 3 x 2-3 | D24: — | E24: 265 lb | F24: RPE 8
A25: Accessory | B25: Incline DB Press | C25: 3 | D25: 8-10 | E25: Heavy DBs | F25: RPE 8
A26: Accessory | B26: Face Pull | C26: 3 | D26: 12-20 | E26: Cable | F26: RPE 7
A27: Carry | B27: Farmer Carry | C27: 4 | D27: 40-60 m | E27: Heavy | F27: RPE 8
A28: Run | B28: Intervals | C28: 1 | D28: 6 x 800m | E28: Warm-up/cooldown included | F28: RPE 8
A31: Day 3 - Pull Hypertrophy + Tempo Run
A32: Category | B32: Exercise / Session | C32: Sets | D32: Reps / Distance | E32: Planned Load / Time / Pace | F32: Target RPE / Zone | G32: Actual Load / Time | H32: Actual Reps / Distance | I32: Actual RPE | J32: Done? | K32: Notes
A33: Strength | B33: Deadlift | C33: 3 x 1-2 | D33: — | E33: 485 lb | F33: RPE 8-9
A34: Accessory | B34: Chest-Supported Row | C34: 4 | D34: 8-12 | E34: Progress weekly | F34: RPE 8
A35: Accessory | B35: Lat Pulldown | C35: 4 | D35: 10-12 | E35: Progress weekly | F35: RPE 8
A36: Accessory | B36: Seated Cable Row | C36: 3 | D36: 10-12 | E36: Progress weekly | F36: RPE 8
A37: Accessory | B37: Rear Delt Fly | C37: 4 | D37: 12-20 | E37: Strict | F37: RPE 8
A38: Accessory | B38: DB Curl | C38: 3 | D38: 8-12 | E38: Strict | F38: RPE 8
A39: Accessory | B39: Hammer Curl | C39: 3 | D39: 10-12 | E39: Strict | F39: RPE 8
A40: Run | B40: Tempo Run | C40: 1 | D40: 3 x 10 min tempo | E40: Comfortably hard | F40: RPE 7-8
A43: Day 4 - Push Hypertrophy + Low-Impact Cardio
A44: Category | B44: Exercise / Session | C44: Sets | D44: Reps / Distance | E44: Planned Load / Time / Pace | F44: Target RPE / Zone | G44: Actual Load / Time | H44: Actual Reps / Distance | I44: Actual RPE | J44: Done? | K44: Notes
A45: Strength | B45: Incline Bench Press | C45: 4 | D45: 6-8 | E45: 245 lb | F45: RPE 8
A46: Accessory | B46: DB Shoulder Press | C46: 4 | D46: 8-10 | E46: Heavy DBs | F46: RPE 8
A47: Strength | B47: Weighted Dip | C47: 3-4 | D47: 6-10 | E47: +75 lb | F47: RPE 8
A48: Accessory | B48: Cable Fly | C48: 3 | D48: 12-15 | E48: Controlled | F48: RPE 8
...

Sheet Week 12
A1: Week 12 - Heavy Hybrid Plan | Day-by-Day Log
A3: Planned Run Miles | B3: 20 | C3: Actual Run Miles | E3: Avg Sleep | G3: Stress 1-10 | I3: Bodyweight
A4: Notes
A5: Readiness Formula | B5: =(10-F3)+(10-H3)+IF(F3="",0,F3) -> 20
A6: Weekly Goal | B6: Push heavy but recoverable. No missed reps unless Week 12 testing.
A8: Day 1 - Lower Strength + Easy Run
A9: Category | B9: Exercise / Session | C9: Sets | D9: Reps / Distance | E9: Planned Load / Time / Pace | F9: Target RPE / Zone | G9: Actual Load / Time | H9: Actual Reps / Distance | I9: Actual RPE | J9: Done? | K9: Notes
A10: Strength | B10: Back Squat | C10: Work up to test set | D10: — | E10: Test or 365 lb AMRAP cap 6 | F10: RPE 8-9
A11: Strength | B11: Romanian Deadlift | C11: 3 x 5 | D11: — | E11: 315 lb | F11: RPE 8
A12: Accessory | B12: Bulgarian Split Squat | C12: 3-4 | D12: 8-10/leg | E12: Heavy DBs | F12: RPE 8
A13: Accessory | B13: Seated Leg Curl | C13: 3-4 | D13: 10-12 | E13: Progress weekly | F13: RPE 8
A14: Accessory | B14: Standing Calf Raise | C14: 4 | D14: 8-12 | E14: Heavy | F14: RPE 8
A15: Core | B15: Hanging Leg Raise | C15: 3 | D15: 10-15 | E15: Bodyweight/weighted | F15: RPE 7-8
A16: Run | B16: Easy Zone 2 Run | C16: 1 | D16: 3 mi | E16: Pace 9:20-10:20/mi | F16: Zone 2
A19: Day 2 - Upper Strength + Intervals
A20: Category | B20: Exercise / Session | C20: Sets | D20: Reps / Distance | E20: Planned Load / Time / Pace | F20: Target RPE / Zone | G20: Actual Load / Time | H20: Actual Reps / Distance | I20: Actual RPE | J20: Done? | K20: Notes
A21: Strength | B21: Bench Press | C21: Work up to test set | D21: — | E21: Test or 255 lb speed work | F21: RPE 8-9
A22: Strength | B22: Weighted Pull-Up | C22: Test | D22: — | E22: Test max reps or load | F22: RPE 8-9
A23: Strength | B23: Overhead Press | C23: Work up to test set | D23: — | E23: Test or 115 lb speed work | F23: RPE 8
A24: Strength | B24: Barbell Row | C24: 3 x 5 | D24: — | E24: 225 lb crisp | F24: RPE 8
A25: Accessory | B25: Incline DB Press | C25: 3 | D25: 8-10 | E25: Heavy DBs | F25: RPE 8
A26: Accessory | B26: Face Pull | C26: 3 | D26: 12-20 | E26: Cable | F26: RPE 7
A27: Carry | B27: Farmer Carry | C27: 4 | D27: 40-60 m | E27: Heavy | F27: RPE 8
A28: Run | B28: Intervals | C28: 1 | D28: 2-mile test or 1-mile test | E28: Warm-up/cooldown included | F28: RPE 8
A31: Day 3 - Pull Hypertrophy + Tempo Run
A32: Category | B32: Exercise / Session | C32: Sets | D32: Reps / Distance | E32: Planned Load / Time / Pace | F32: Target RPE / Zone | G32: Actual Load / Time | H32: Actual Reps / Distance | I32: Actual RPE | J32: Done? | K32: Notes
A33: Strength | B33: Deadlift | C33: Work up to test set | D33: — | E33: Test or 405 lb speed work | F33: RPE 8-9
A34: Accessory | B34: Chest-Supported Row | C34: 4 | D34: 8-12 | E34: Progress weekly | F34: RPE 8
A35: Accessory | B35: Lat Pulldown | C35: 4 | D35: 10-12 | E35: Progress weekly | F35: RPE 8
A36: Accessory | B36: Seated Cable Row | C36: 3 | D36: 10-12 | E36: Progress weekly | F36: RPE 8
A37: Accessory | B37: Rear Delt Fly | C37: 4 | D37: 12-20 | E37: Strict | F37: RPE 8
A38: Accessory | B38: DB Curl | C38: 3 | D38: 8-12 | E38: Strict | F38: RPE 8
A39: Accessory | B39: Hammer Curl | C39: 3 | D39: 10-12 | E39: Strict | F39: RPE 8
A40: Run | B40: Tempo Run | C40: 1 | D40: 15 min relaxed tempo | E40: Comfortably hard | F40: RPE 7-8
A43: Day 4 - Push Hypertrophy + Low-Impact Cardio
A44: Category | B44: Exercise / Session | C44: Sets | D44: Reps / Distance | E44: Planned Load / Time / Pace | F44: Target RPE / Zone | G44: Actual Load / Time | H44: Actual Reps / Distance | I44: Actual RPE | J44: Done? | K44: Notes
A45: Strength | B45: Incline Bench Press | C45: 4 | D45: 6-8 | E45: 205 lb | F45: RPE 8
A46: Accessory | B46: DB Shoulder Press | C46: 4 | D46: 8-10 | E46: Heavy DBs | F46: RPE 8
A47: Strength | B47: Weighted Dip | C47: 3-4 | D47: 6-10 | E47: Test or +35 lb | F47: RPE 8
A48: Accessory | B48: Cable Fly | C48: 3 | D48: 12-15 | E48: Controlled | F48: RPE 8
...

Sheet Instructions
A1: How to Use This Workbook
A3: Step | B3: What to do
A4: 1 | B4: Open the current Week tab.
A5: 2 | B5: Each Week tab is separated into Day 1 through Day 7 sections.
A6: 3 | B6: Before training, review planned load, sets, reps/distance, and target RPE.
A7: 4 | B7: After training, enter Actual Load/Time, Actual Reps/Distance, Actual RPE, Done status, and Notes.
A8: 5 | B8: At the top of each Week tab, log actual running miles, sleep, stress, and bodyweight.
A9: 6 | B9: Keep heavy sets hard but avoid sloppy grinders unless intentionally testing in Week 12.
A10: 7 | B10: If shin/knee/Achilles pain appears, reduce plyometrics or speed first before cutting easy Zone 2 work.
A12: New Tab Added | B12: Cardio Details: full warm-ups, main work, cool-downs, weekly mileage checks, and coaching notes for each cardio session.
A13: How to Use | B13: Use planned miles as your target; log Actual Miles/Time and Notes after each cardio session.

Sheet Cardio Details
A1: Cardio Workouts - Full Warm-Up / Main Work / Cool-Down Guide
A2: Use this tab to understand exactly how each cardio session reaches the weekly running mileage target. Day 4 counts as cardio but not running mileage. Day 7 is plyometrics/mobility and should not add run mileage.
A4: Week | B4: Day | C4: Cardio Session | D4: Warm-up Miles | E4: Main Work Details | F4: Cool-down Miles | G4: Planned Run Miles | H4: Intensity / Pace | I4: Coaching Notes | J4: Actual Miles/Time | K4: Notes
A5: 1 | B5: Day 1 | C5: Easy Zone 2 Run | D5: 0.25 | E5: 2.50 mi easy continuous | F5: 0.25 | G5: 3 | H5: Easy conversational pace; roughly 9:20-10:20/mi unless fatigue is high. | I5: Keep this boring. Its job is aerobic volume without beating up your legs.
A6: 1 | B6: Day 2 | C6: Intervals | D6: 1 | E6: 6 × 400m @ controlled hard + jog/walk recoveries; fill remaining ~1.50 mi | F6: 0.5 | G6: 3 | H6: Fast reps at RPE 8; recoveries easy. Never all-out sprint these. | I6: The warm-up/cool-down are part of the mileage. Add easy jogging after intervals if short.
A7: 1 | B7: Day 3 | C7: Tempo Run | D7: 1 | E7: 15 min tempo; use easy running before/after tempo to reach ~1.50 mi main block | F7: 1 | G7: 3.5 | H7: RPE 7-8; comfortably hard, not a race. | I7: You should be able to speak in short phrases. Reduce pace if leg fatigue hurts lifting.
A8: 1 | B8: Day 4 | C8: Low-Impact Zone 2 | D8: 0 | E8: 35-45 min Zone 2 bike / incline walk / elliptical / rower | F8: 0 | G8: 0 | H8: RPE 4-5; nasal-breathing/conversational effort. | I8: This counts as cardio but not running mileage. Use it to build engine without extra impact.
A9: 1 | B9: Day 5 | C9: Strides / Speed Mechanics | D9: 1 | E9: 6 × 100m strides; walk-back/full recovery; add easy running to make ~0.50 mi | F9: 1 | G9: 2.5 | H9: Fast, relaxed, technically clean; RPE 6-7 except brief fast strides. | I9: This is speed skill, not conditioning. Stop if mechanics get sloppy.
A10: 1 | B10: Day 6 | C10: Long Easy Run | D10: 0.25 | E10: 3.50 mi easy continuous | F10: 0.25 | G10: 4 | H10: Easy Zone 2. Start slower than you think. | I10: This is the anchor aerobic session. Do not race it.
A11: 1 | B11: Day 7 | C11: Plyometrics + Mobility | D11: 0 | E11: No running mileage. Low-volume jumps + med-ball power + mobility. | F11: 0 | G11: 0 | H11: Crisp, low fatigue. RPE 6-7. | I11: If shins/Achilles/knees are irritated, replace jumps with mobility and tissue prep.
A12: 2 | B12: Day 1 | C12: Easy Zone 2 Run | D12: 0.25 | E12: 3.00 mi easy continuous | F12: 0.25 | G12: 3.5 | H12: Easy conversational pace; roughly 9:20-10:20/mi unless fatigue is high. | I12: Keep this boring. Its job is aerobic volume without beating up your legs.
A13: 2 | B13: Day 2 | C13: Intervals | D13: 1 | E13: 8 × 400m @ controlled hard + jog/walk recoveries; fill remaining ~2.00 mi | F13: 0.5 | G13: 3.5 | H13: Fast reps at RPE 8; recoveries easy. Never all-out sprint these. | I13: The warm-up/cool-down are part of the mileage. Add easy jogging after intervals if short.
A14: 2 | B14: Day 3 | C14: Tempo Run | D14: 1 | E14: 18 min tempo; use easy running before/after tempo to reach ~2.00 mi main block | F14: 1 | G14: 4 | H14: RPE 7-8; comfortably hard, not a race. | I14: You should be able to speak in short phrases. Reduce pace if leg fatigue hurts lifting.
A15: 2 | B15: Day 4 | C15: Low-Impact Zone 2 | D15: 0 | E15: 35-45 min Zone 2 bike / incline walk / elliptical / rower | F15: 0 | G15: 0 | H15: RPE 4-5; nasal-breathing/conversational effort. | I15: This counts as cardio but not running mileage. Use it to build engine without extra impact.
A16: 2 | B16: Day 5 | C16: Strides / Speed Mechanics | D16: 1 | E16: 8 × 100m strides; walk-back/full recovery; add easy running to make ~0.00 mi | F16: 1 | G16: 2 | H16: Fast, relaxed, technically clean; RPE 6-7 except brief fast strides. | I16: This is speed skill, not conditioning. Stop if mechanics get sloppy.
... A88: 12 | B88: Day 7 | C88: Plyometrics + Mobility | D88: 0 | E88: No running mileage. Low-volume jumps + med-ball power + mobility. | F88: 0 | G88: 0 | H88: Crisp, low fatigue. RPE 6-7. | I88: If shins/Achilles/knees are irritated, replace jumps with mobility and tissue prep.
A91: Weekly Running Mileage Check | F91: Cardio Progression Rules
A92: Week | B92: Target Miles | C92: Planned Miles From Rows | D92: Difference | F92: 1 | G92: Increase mileage only when lower legs feel good: calves, shins, knees, hips, and Achilles.
A93: 1 | B93: 16 | C93: =SUMIF($A$5:$A$88,A93,$G$5:$G$88) -> 16 | D93: =C93-B93 -> 0 | F93: 2 | G93: Keep easy runs easy. Your hard cardio sessions are intervals and tempo; the long run should stay controlled.
A94: 2 | B94: 18 | C94: =SUMIF($A$5:$A$88,A94,$G$5:$G$88) -> 18 | D94: =C94-B94 -> 0 | F94: 3 | G94: Warm-up/cool-down mileage counts toward weekly mileage. Do not add extra miles unless you intentionally progress the plan.
A95: 3 | B95: 20 | C95: =SUMIF($A$5:$A$88,A95,$G$5:$G$88) -> 20 | D95: =C95-B95 -> 0 | F95: 4 | G95: If lifting performance drops for 2+ sessions, reduce run intensity before reducing all aerobic work.
A96: 4 | B96: 14.5 | C96: =SUMIF($A$5:$A$88,A96,$G$5:$G$88) -> 14.5 | D96: =C96-B96 -> 0 | F96: 5 | G96: If pain appears, remove strides/plyos first, then replace one run with low-impact Zone 2.
A97: 5 | B97: 21 | C97: =SUMIF($A$5:$A$88,A97,$G$5:$G$88) -> 21 | D97: =C97-B97 -> 0
A98: 6 | B98: 23 | C98: =SUMIF($A$5:$A$88,A98,$G$5:$G$88) -> 23 | D98: =C98-B98 -> 0
A99: 7 | B99: 25 | C99: =SUMIF($A$5:$A$88,A99,$G$5:$G$88) -> 25 | D99: =C99-B99 -> 0
A100: 8 | B100: 17.5 | C100: =SUMIF($A$5:$A$88,A100,$G$5:$G$88) -> 17.5 | D100: =C100-B100 -> 0
A101: 9 | B101: 26 | C101: =SUMIF($A$5:$A$88,A101,$G$5:$G$88) -> 26 | D101: =C101-B101 -> 0
A102: 10 | B102: 28 | C102: =SUMIF($A$5:$A$88,A102,$G$5:$G$88) -> 28 | D102: =C102-B102 -> 0
A103: 11 | B103: 30 | C103: =SUMIF($A$5:$A$88,A103,$G$5:$G$88) -> 30 | D103: =C103-B103 -> 0
A104: 12 | B104: 20 | C104: =SUMIF($A$5:$A$88,A104,$G$5:$G$88) -> 20 | D104: =C104-B104 -> 0
